Traceback (most recent call last):
  File "C:\Users\USER\miniconda3\envs\ml_tf\lib\site-packages\jupyter_cache\executors\utils.py", line 58, in single_nb_execution
    executenb(
  File "C:\Users\USER\miniconda3\envs\ml_tf\lib\site-packages\nbclient\client.py", line 1305, in execute
    return NotebookClient(nb=nb, resources=resources, km=km, **kwargs).execute()
  File "C:\Users\USER\miniconda3\envs\ml_tf\lib\site-packages\jupyter_core\utils\__init__.py", line 173, in wrapped
    return loop.run_until_complete(inner)
  File "C:\Users\USER\miniconda3\envs\ml_tf\lib\asyncio\base_events.py", line 647, in run_until_complete
    return future.result()
  File "C:\Users\USER\miniconda3\envs\ml_tf\lib\site-packages\nbclient\client.py", line 705, in async_execute
    await self.async_execute_cell(
  File "C:\Users\USER\miniconda3\envs\ml_tf\lib\site-packages\nbclient\client.py", line 1058, in async_execute_cell
    await self._check_raise_for_error(cell, cell_index, exec_reply)
  File "C:\Users\USER\miniconda3\envs\ml_tf\lib\site-packages\nbclient\client.py", line 914, in _check_raise_for_error
    raise CellExecutionError.from_cell_and_msg(cell, exec_reply_content)
nbclient.exceptions.CellExecutionError: An error occurred while executing the following cell:
------------------
import numpy as np
import pandas as pd
import tensorflow as tf
import os
from keras.preprocessing.image import ImageDataGenerator
from tensorflow.keras.utils import load_img
from keras.layers import Conv2D, Dense, BatchNormalization, Activation, Dropout, MaxPooling2D, Flatten
from tensorflow.keras.optimizers import Adam, RMSprop, SGD
from keras.callbacks import ModelCheckpoint,EarlyStopping
import datetime
from keras import regularizers
import matplotlib.pyplot as plt
from keras.utils.vis_utils import plot_model
------------------


[1;31m---------------------------------------------------------------------------[0m
[1;31mImportError[0m                               Traceback (most recent call last)
Cell [1;32mIn[66], line 5[0m
[0;32m      3[0m [38;5;28;01mimport[39;00m [38;5;21;01mtensorflow[39;00m [38;5;28;01mas[39;00m [38;5;21;01mtf[39;00m
[0;32m      4[0m [38;5;28;01mimport[39;00m [38;5;21;01mos[39;00m
[1;32m----> 5[0m [38;5;28;01mfrom[39;00m [38;5;21;01mkeras[39;00m[38;5;21;01m.[39;00m[38;5;21;01mpreprocessing[39;00m[38;5;21;01m.[39;00m[38;5;21;01mimage[39;00m [38;5;28;01mimport[39;00m ImageDataGenerator
[0;32m      6[0m [38;5;28;01mfrom[39;00m [38;5;21;01mtensorflow[39;00m[38;5;21;01m.[39;00m[38;5;21;01mkeras[39;00m[38;5;21;01m.[39;00m[38;5;21;01mutils[39;00m [38;5;28;01mimport[39;00m load_img
[0;32m      7[0m [38;5;28;01mfrom[39;00m [38;5;21;01mkeras[39;00m[38;5;21;01m.[39;00m[38;5;21;01mlayers[39;00m [38;5;28;01mimport[39;00m Conv2D, Dense, BatchNormalization, Activation, Dropout, MaxPooling2D, Flatten

[1;31mImportError[0m: cannot import name 'ImageDataGenerator' from 'keras.preprocessing.image' (C:\Users\USER\miniconda3\envs\ml_tf\lib\site-packages\keras\api\preprocessing\image\__init__.py)

